2023-02-09 21:08:38,908 DEBUG   MainThread:914074 [wandb_config.py:_load_defaults():119] no defaults not found in config-defaults.yaml
2023-02-09 21:08:38,914 DEBUG   MainThread:914074 [meta.py:setup():97] code probe starting
2023-02-09 21:08:38,922 DEBUG   MainThread:914074 [git_repo.py:repo():30] git repository is invalid
2023-02-09 21:08:38,922 DEBUG   MainThread:914074 [meta.py:_setup_code_program():58] save program starting
2023-02-09 21:08:38,922 DEBUG   MainThread:914074 [meta.py:_setup_code_program():60] save program starting: /scratch/trafficdriving/carla_project/src/traffic_map_model.py
2023-02-09 21:08:38,922 DEBUG   MainThread:914074 [meta.py:_setup_code_program():65] save program saved: /scratch/trafficdriving/results/phase1/test_ppo/wandb/run-20230210_020838-test_ppo/code/carla_project/src/traffic_map_model.py
2023-02-09 21:08:38,922 DEBUG   MainThread:914074 [meta.py:_setup_code_program():67] save program
2023-02-09 21:08:38,923 DEBUG   MainThread:914074 [meta.py:setup():119] code probe done
2023-02-09 21:08:38,965 DEBUG   MainThread:914074 [run_manager.py:__init__():541] Initialized sync for ppo_mapmodel/test_ppo
2023-02-09 21:08:38,969 INFO    MainThread:914074 [run_manager.py:wrap_existing_process():1144] wrapping existing process 913974
2023-02-09 21:08:38,970 WARNING MainThread:914074 [io_wrap.py:register():104] SIGWINCH handler was not None: <Handlers.SIG_DFL: 0>
2023-02-09 21:08:38,972 DEBUG   MainThread:914074 [connectionpool.py:_new_conn():1003] Starting new HTTPS connection (1): pypi.org:443
2023-02-09 21:08:39,002 DEBUG   MainThread:914074 [connectionpool.py:_make_request():456] https://pypi.org:443 "GET /pypi/wandb/json HTTP/1.1" 200 74008
2023-02-09 21:08:39,021 INFO    MainThread:914074 [run_manager.py:init_run():924] system metrics and metadata threads started
2023-02-09 21:08:39,021 INFO    MainThread:914074 [run_manager.py:init_run():933] checking resume status, waiting at most 10 seconds
2023-02-09 21:08:39,027 DEBUG   Thread-14 :914074 [connectionpool.py:_new_conn():1003] Starting new HTTPS connection (1): api.wandb.ai:443
2023-02-09 21:08:39,097 DEBUG   Thread-14 :914074 [connectionpool.py:_make_request():456] https://api.wandb.ai:443 "POST /graphql HTTP/1.1" 200 140
2023-02-09 21:08:39,100 INFO    MainThread:914074 [run_manager.py:init_run():963] upserting run before process can begin, waiting at most 10 seconds
2023-02-09 21:08:39,104 DEBUG   Thread-15 :914074 [connectionpool.py:_new_conn():1003] Starting new HTTPS connection (1): api.wandb.ai:443
2023-02-09 21:08:39,187 DEBUG   Thread-15 :914074 [connectionpool.py:_make_request():456] https://api.wandb.ai:443 "POST /graphql HTTP/1.1" 409 136
2023-02-09 21:08:39,189 ERROR   Thread-15 :914074 [internal.py:execute():113] 409 response executing GraphQL.
2023-02-09 21:08:39,190 ERROR   Thread-15 :914074 [internal.py:execute():114] {"errors":[{"message":"run laurayuzheng/ppo_mapmodel/test_ppo was previously created and deleted; try a new run name","path":["upsertBucket"]}],"data":{"upsertBucket":null}}
2023-02-09 21:08:39,913 INFO    Thread-3  :914074 [run_manager.py:_on_file_modified():688] file/dir modified: /scratch/trafficdriving/results/phase1/test_ppo/wandb/run-20230210_020838-test_ppo/config.yaml
2023-02-09 21:08:40,356 DEBUG   Thread-15 :914074 [connectionpool.py:_new_conn():1003] Starting new HTTPS connection (1): api.wandb.ai:443
2023-02-09 21:08:40,436 DEBUG   Thread-15 :914074 [connectionpool.py:_make_request():456] https://api.wandb.ai:443 "POST /graphql HTTP/1.1" 409 136
2023-02-09 21:08:40,439 ERROR   Thread-15 :914074 [internal.py:execute():113] 409 response executing GraphQL.
2023-02-09 21:08:40,439 ERROR   Thread-15 :914074 [internal.py:execute():114] {"errors":[{"message":"run laurayuzheng/ppo_mapmodel/test_ppo was previously created and deleted; try a new run name","path":["upsertBucket"]}],"data":{"upsertBucket":null}}
2023-02-09 21:08:42,524 DEBUG   Thread-15 :914074 [connectionpool.py:_new_conn():1003] Starting new HTTPS connection (1): api.wandb.ai:443
2023-02-09 21:08:42,596 DEBUG   Thread-15 :914074 [connectionpool.py:_make_request():456] https://api.wandb.ai:443 "POST /graphql HTTP/1.1" 409 136
2023-02-09 21:08:42,598 ERROR   Thread-15 :914074 [internal.py:execute():113] 409 response executing GraphQL.
2023-02-09 21:08:42,599 ERROR   Thread-15 :914074 [internal.py:execute():114] {"errors":[{"message":"run laurayuzheng/ppo_mapmodel/test_ppo was previously created and deleted; try a new run name","path":["upsertBucket"]}],"data":{"upsertBucket":null}}
2023-02-09 21:08:42,599 ERROR   Thread-15 :914074 [retry.py:__call__():108] Retry attempt failed:
Traceback (most recent call last):
  File "/home/laura/anaconda3/envs/icra23/lib/python3.8/site-packages/wandb/retry.py", line 95, in __call__
    result = self._call_fn(*args, **kwargs)
  File "/home/laura/anaconda3/envs/icra23/lib/python3.8/site-packages/wandb/apis/internal.py", line 116, in execute
    six.reraise(*sys.exc_info())
  File "/home/laura/anaconda3/envs/icra23/lib/python3.8/site-packages/six.py", line 719, in reraise
    raise value
  File "/home/laura/anaconda3/envs/icra23/lib/python3.8/site-packages/wandb/apis/internal.py", line 110, in execute
    return self.client.execute(*args, **kwargs)
  File "/home/laura/anaconda3/envs/icra23/lib/python3.8/site-packages/gql/client.py", line 52, in execute
    result = self._get_result(document, *args, **kwargs)
  File "/home/laura/anaconda3/envs/icra23/lib/python3.8/site-packages/gql/client.py", line 60, in _get_result
    return self.transport.execute(document, *args, **kwargs)
  File "/home/laura/anaconda3/envs/icra23/lib/python3.8/site-packages/gql/transport/requests.py", line 39, in execute
    request.raise_for_status()
  File "/home/laura/anaconda3/envs/icra23/lib/python3.8/site-packages/requests/models.py", line 1021, in raise_for_status
    raise HTTPError(http_error_msg, response=self)
requests.exceptions.HTTPError: 409 Client Error: Conflict for url: https://api.wandb.ai/graphql
2023-02-09 21:08:46,745 DEBUG   Thread-15 :914074 [connectionpool.py:_new_conn():1003] Starting new HTTPS connection (1): api.wandb.ai:443
2023-02-09 21:08:46,836 DEBUG   Thread-15 :914074 [connectionpool.py:_make_request():456] https://api.wandb.ai:443 "POST /graphql HTTP/1.1" 409 136
2023-02-09 21:08:46,840 ERROR   Thread-15 :914074 [internal.py:execute():113] 409 response executing GraphQL.
2023-02-09 21:08:46,840 ERROR   Thread-15 :914074 [internal.py:execute():114] {"errors":[{"message":"run laurayuzheng/ppo_mapmodel/test_ppo was previously created and deleted; try a new run name","path":["upsertBucket"]}],"data":{"upsertBucket":null}}
2023-02-09 21:08:49,105 ERROR   MainThread:914074 [run_manager.py:init_run():967] Failed to connect to W&B servers after 10 seconds.                    Letting user process proceed while attempting to reconnect.
2023-02-09 21:08:49,105 INFO    MainThread:914074 [run_manager.py:wrap_existing_process():1161] informing user process we are ready to proceed
2023-02-09 21:08:49,110 DEBUG   Thread-16 :914074 [connectionpool.py:_new_conn():1003] Starting new HTTPS connection (1): api.wandb.ai:443
2023-02-09 21:08:49,111 INFO    MainThread:914074 [run_manager.py:_sync_etc():1268] entering loop for messages from user process
2023-02-09 21:08:49,128 INFO    MainThread:914074 [run_manager.py:_sync_etc():1291] received message from user process: {"exitcode": 1}
2023-02-09 21:08:49,128 INFO    MainThread:914074 [run_manager.py:_sync_etc():1377] closing log streams and sending exitcode to W&B
2023-02-09 21:08:49,129 INFO    MainThread:914074 [run_manager.py:shutdown():1068] shutting down system stats and metadata service
2023-02-09 21:08:49,317 DEBUG   Thread-16 :914074 [connectionpool.py:_make_request():456] https://api.wandb.ai:443 "POST /graphql HTTP/1.1" 200 36
2023-02-09 21:08:50,035 INFO    MainThread:914074 [run_manager.py:shutdown():1080] stopping streaming files and file change observer
2023-02-09 21:08:56,084 DEBUG   Thread-15 :914074 [connectionpool.py:_new_conn():1003] Starting new HTTPS connection (1): api.wandb.ai:443
2023-02-09 21:08:56,162 DEBUG   Thread-15 :914074 [connectionpool.py:_make_request():456] https://api.wandb.ai:443 "POST /graphql HTTP/1.1" 409 136
2023-02-09 21:08:56,164 ERROR   Thread-15 :914074 [internal.py:execute():113] 409 response executing GraphQL.
2023-02-09 21:08:56,165 ERROR   Thread-15 :914074 [internal.py:execute():114] {"errors":[{"message":"run laurayuzheng/ppo_mapmodel/test_ppo was previously created and deleted; try a new run name","path":["upsertBucket"]}],"data":{"upsertBucket":null}}
77] closing log streams and sending exitcode to W&B
2023-02-09 21:08:49,129 INFO    MainThread:914074 [test_ppo:run_manager.py:shutdown():1068] shutting down system stats and metadata service
2023-02-09 21:08:50,035 INFO    MainThread:914074 [test_ppo:run_manager.py:shutdown():1080] stopping streaming files and file change observer
2023-02-09 21:08:56,164 ERROR   Thread-15 :914074 [test_ppo:internal.py:execute():113] 409 response executing GraphQL.
2023-02-09 21:08:56,165 ERROR   Thread-15 :914074 [test_ppo:internal.py:execute():114] {"errors":[{"message":"run laurayuzheng/ppo_mapmodel/test_ppo was previously created and deleted; try a new run name","path":["upsertBucket"]}],"data":{"upsertBucket":null}}
